2025-03-19 19:52:24,969 ERROR: Exception on /projects [GET] [in /Users/rtm/Documents/GitHub/work/utils/online-poc-mgmt/.venv/lib/python3.11/site-packages/flask/app.py:828]
Traceback (most recent call last):
  File "/Users/rtm/Documents/GitHub/work/utils/online-poc-mgmt/.venv/lib/python3.11/site-packages/flask/app.py", line 1463, in wsgi_app
    response = self.full_dispatch_request()
               ^^^^^^^^^^^^^^^^^^^^^^^^^^^^
  File "/Users/rtm/Documents/GitHub/work/utils/online-poc-mgmt/.venv/lib/python3.11/site-packages/flask/app.py", line 872, in full_dispatch_request
    rv = self.handle_user_exception(e)
         ^^^^^^^^^^^^^^^^^^^^^^^^^^^^^
  File "/Users/rtm/Documents/GitHub/work/utils/online-poc-mgmt/.venv/lib/python3.11/site-packages/flask/app.py", line 870, in full_dispatch_request
    rv = self.dispatch_request()
         ^^^^^^^^^^^^^^^^^^^^^^^
  File "/Users/rtm/Documents/GitHub/work/utils/online-poc-mgmt/.venv/lib/python3.11/site-packages/flask/app.py", line 855, in dispatch_request
    return self.ensure_sync(self.view_functions[rule.endpoint])(**view_args)  # type: ignore[no-any-return]
           ^^^^^^^^^^^^^^^^^^^^^^^^^^^^^^^^^^^^^^^^^^^^^^^^^^^^^^^^^^^^^^^^^
  File "/Users/rtm/Documents/GitHub/work/utils/online-poc-mgmt/app/routes.py", line 100, in projects
    projects = Project.query.order_by(Project.created_at.desc()).all()
               ^^^^^^^^^^^^^^^^^^^^^^^^^^^^^^^^^^^^^^^^^^^^^^^^^^^^^^^
  File "/Users/rtm/Documents/GitHub/work/utils/online-poc-mgmt/.venv/lib/python3.11/site-packages/sqlalchemy/orm/query.py", line 2672, in all
    return self._iter().all()  # type: ignore
           ^^^^^^^^^^^^
  File "/Users/rtm/Documents/GitHub/work/utils/online-poc-mgmt/.venv/lib/python3.11/site-packages/sqlalchemy/orm/query.py", line 2826, in _iter
    result: Union[ScalarResult[_T], Result[_T]] = self.session.execute(
                                                  ^^^^^^^^^^^^^^^^^^^^^
  File "/Users/rtm/Documents/GitHub/work/utils/online-poc-mgmt/.venv/lib/python3.11/site-packages/sqlalchemy/orm/session.py", line 2306, in execute
    return self._execute_internal(
           ^^^^^^^^^^^^^^^^^^^^^^^
  File "/Users/rtm/Documents/GitHub/work/utils/online-poc-mgmt/.venv/lib/python3.11/site-packages/sqlalchemy/orm/session.py", line 2179, in _execute_internal
    bind = self.get_bind(**bind_arguments)
           ^^^^^^^^^^^^^^^^^^^^^^^^^^^^^^^
  File "/Users/rtm/Documents/GitHub/work/utils/online-poc-mgmt/.venv/lib/python3.11/site-packages/flask_sqlalchemy/session.py", line 53, in get_bind
    engines = self._db.engines
              ^^^^^^^^^^^^^^^^
  File "/Users/rtm/Documents/GitHub/work/utils/online-poc-mgmt/.venv/lib/python3.11/site-packages/flask_sqlalchemy/extension.py", line 690, in engines
    raise RuntimeError(
RuntimeError: The current Flask app is not registered with this 'SQLAlchemy' instance. Did you forget to call 'init_app', or did you create multiple 'SQLAlchemy' instances?
2025-03-19 19:53:22,084 INFO: POC Management startup [in /Users/rtm/Documents/GitHub/work/utils/online-poc-mgmt/app/__init__.py:41]
2025-03-19 19:53:22,457 INFO: POC Management startup [in /Users/rtm/Documents/GitHub/work/utils/online-poc-mgmt/app/__init__.py:41]
2025-03-19 19:54:07,427 INFO: POC Management startup [in /Users/rtm/Documents/GitHub/work/utils/online-poc-mgmt/app/__init__.py:38]
2025-03-19 19:54:10,084 INFO: POC Management startup [in /Users/rtm/Documents/GitHub/work/utils/online-poc-mgmt/app/__init__.py:38]
2025-03-19 19:54:18,680 INFO: POC Management startup [in /Users/rtm/Documents/GitHub/work/utils/online-poc-mgmt/app/__init__.py:38]
2025-03-19 19:54:19,026 INFO: POC Management startup [in /Users/rtm/Documents/GitHub/work/utils/online-poc-mgmt/app/__init__.py:38]
2025-03-19 19:57:33,905 INFO: POC Management startup [in /Users/rtm/Documents/GitHub/work/utils/online-poc-mgmt/app/__init__.py:38]
2025-03-19 19:57:34,255 INFO: POC Management startup [in /Users/rtm/Documents/GitHub/work/utils/online-poc-mgmt/app/__init__.py:38]
2025-03-19 19:58:57,779 INFO: POC Management startup [in /Users/rtm/Documents/GitHub/work/utils/online-poc-mgmt/app/__init__.py:38]
2025-03-19 19:59:44,553 INFO: POC Management startup [in /Users/rtm/Documents/GitHub/work/utils/online-poc-mgmt/app/__init__.py:38]
2025-03-19 20:00:38,802 INFO: POC Management startup [in /Users/rtm/Documents/GitHub/work/utils/online-poc-mgmt/app/__init__.py:38]
2025-03-19 20:00:39,148 INFO: POC Management startup [in /Users/rtm/Documents/GitHub/work/utils/online-poc-mgmt/app/__init__.py:38]
2025-03-19 20:01:44,377 INFO: POC Management startup [in /Users/rtm/Documents/GitHub/work/utils/online-poc-mgmt/app/__init__.py:38]
2025-03-19 20:01:44,731 INFO: POC Management startup [in /Users/rtm/Documents/GitHub/work/utils/online-poc-mgmt/app/__init__.py:38]
2025-03-19 20:02:47,159 INFO: POC Management startup [in /Users/rtm/Documents/GitHub/work/utils/online-poc-mgmt/app/__init__.py:38]
2025-03-19 20:02:52,100 INFO: POC Management startup [in /Users/rtm/Documents/GitHub/work/utils/online-poc-mgmt/app/__init__.py:38]
2025-03-19 20:03:10,172 INFO: POC Management startup [in /Users/rtm/Documents/GitHub/work/utils/online-poc-mgmt/app/__init__.py:38]
2025-03-19 20:04:03,811 INFO: POC Management startup [in /Users/rtm/Documents/GitHub/work/utils/online-poc-mgmt/app/__init__.py:38]
