2025-03-19 19:35:45,388 INFO: POC Management startup [in /Users/rtm/Documents/GitHub/work/utils/online-poc-mgmt/app/__init__.py:40]
2025-03-19 19:35:57,944 INFO: POC Management startup [in /Users/rtm/Documents/GitHub/work/utils/online-poc-mgmt/app/__init__.py:40]
2025-03-19 19:36:31,869 ERROR: Exception on /projects [GET] [in /Users/rtm/Documents/GitHub/work/utils/online-poc-mgmt/.venv/lib/python3.11/site-packages/flask/app.py:828]
Traceback (most recent call last):
  File "/Users/rtm/Documents/GitHub/work/utils/online-poc-mgmt/.venv/lib/python3.11/site-packages/flask/app.py", line 1463, in wsgi_app
    response = self.full_dispatch_request()
               ^^^^^^^^^^^^^^^^^^^^^^^^^^^^
  File "/Users/rtm/Documents/GitHub/work/utils/online-poc-mgmt/.venv/lib/python3.11/site-packages/flask/app.py", line 872, in full_dispatch_request
    rv = self.handle_user_exception(e)
         ^^^^^^^^^^^^^^^^^^^^^^^^^^^^^
  File "/Users/rtm/Documents/GitHub/work/utils/online-poc-mgmt/.venv/lib/python3.11/site-packages/flask/app.py", line 870, in full_dispatch_request
    rv = self.dispatch_request()
         ^^^^^^^^^^^^^^^^^^^^^^^
  File "/Users/rtm/Documents/GitHub/work/utils/online-poc-mgmt/.venv/lib/python3.11/site-packages/flask/app.py", line 855, in dispatch_request
    return self.ensure_sync(self.view_functions[rule.endpoint])(**view_args)  # type: ignore[no-any-return]
           ^^^^^^^^^^^^^^^^^^^^^^^^^^^^^^^^^^^^^^^^^^^^^^^^^^^^^^^^^^^^^^^^^
  File "/Users/rtm/Documents/GitHub/work/utils/online-poc-mgmt/app/routes.py", line 94, in project_list
    projects = Project.query.order_by(Project.created_at.desc()).all()
               ^^^^^^^^^^^^^^^^^^^^^^^^^^^^^^^^^^^^^^^^^^^^^^^^^^^^^^^
  File "/Users/rtm/Documents/GitHub/work/utils/online-poc-mgmt/.venv/lib/python3.11/site-packages/sqlalchemy/orm/query.py", line 2672, in all
    return self._iter().all()  # type: ignore
           ^^^^^^^^^^^^
  File "/Users/rtm/Documents/GitHub/work/utils/online-poc-mgmt/.venv/lib/python3.11/site-packages/sqlalchemy/orm/query.py", line 2826, in _iter
    result: Union[ScalarResult[_T], Result[_T]] = self.session.execute(
                                                  ^^^^^^^^^^^^^^^^^^^^^
  File "/Users/rtm/Documents/GitHub/work/utils/online-poc-mgmt/.venv/lib/python3.11/site-packages/sqlalchemy/orm/session.py", line 2306, in execute
    return self._execute_internal(
           ^^^^^^^^^^^^^^^^^^^^^^^
  File "/Users/rtm/Documents/GitHub/work/utils/online-poc-mgmt/.venv/lib/python3.11/site-packages/sqlalchemy/orm/session.py", line 2179, in _execute_internal
    bind = self.get_bind(**bind_arguments)
           ^^^^^^^^^^^^^^^^^^^^^^^^^^^^^^^
  File "/Users/rtm/Documents/GitHub/work/utils/online-poc-mgmt/.venv/lib/python3.11/site-packages/flask_sqlalchemy/session.py", line 53, in get_bind
    engines = self._db.engines
              ^^^^^^^^^^^^^^^^
  File "/Users/rtm/Documents/GitHub/work/utils/online-poc-mgmt/.venv/lib/python3.11/site-packages/flask_sqlalchemy/extension.py", line 690, in engines
    raise RuntimeError(
RuntimeError: The current Flask app is not registered with this 'SQLAlchemy' instance. Did you forget to call 'init_app', or did you create multiple 'SQLAlchemy' instances?
2025-03-19 19:38:37,199 INFO: POC Management startup [in /Users/rtm/Documents/GitHub/work/utils/online-poc-mgmt/app/__init__.py:40]
2025-03-19 19:38:51,608 ERROR: Exception on /projects [GET] [in /Users/rtm/Documents/GitHub/work/utils/online-poc-mgmt/.venv/lib/python3.11/site-packages/flask/app.py:828]
Traceback (most recent call last):
  File "/Users/rtm/Documents/GitHub/work/utils/online-poc-mgmt/.venv/lib/python3.11/site-packages/flask/app.py", line 1463, in wsgi_app
    response = self.full_dispatch_request()
               ^^^^^^^^^^^^^^^^^^^^^^^^^^^^
  File "/Users/rtm/Documents/GitHub/work/utils/online-poc-mgmt/.venv/lib/python3.11/site-packages/flask/app.py", line 872, in full_dispatch_request
    rv = self.handle_user_exception(e)
         ^^^^^^^^^^^^^^^^^^^^^^^^^^^^^
  File "/Users/rtm/Documents/GitHub/work/utils/online-poc-mgmt/.venv/lib/python3.11/site-packages/flask/app.py", line 870, in full_dispatch_request
    rv = self.dispatch_request()
         ^^^^^^^^^^^^^^^^^^^^^^^
  File "/Users/rtm/Documents/GitHub/work/utils/online-poc-mgmt/.venv/lib/python3.11/site-packages/flask/app.py", line 855, in dispatch_request
    return self.ensure_sync(self.view_functions[rule.endpoint])(**view_args)  # type: ignore[no-any-return]
           ^^^^^^^^^^^^^^^^^^^^^^^^^^^^^^^^^^^^^^^^^^^^^^^^^^^^^^^^^^^^^^^^^
  File "/Users/rtm/Documents/GitHub/work/utils/online-poc-mgmt/app/routes.py", line 95, in projects
    projects = Project.query.order_by(Project.created_at.desc()).all()
               ^^^^^^^^^^^^^^^^^^^^^^^^^^^^^^^^^^^^^^^^^^^^^^^^^^^^^^^
  File "/Users/rtm/Documents/GitHub/work/utils/online-poc-mgmt/.venv/lib/python3.11/site-packages/sqlalchemy/orm/query.py", line 2672, in all
    return self._iter().all()  # type: ignore
           ^^^^^^^^^^^^
  File "/Users/rtm/Documents/GitHub/work/utils/online-poc-mgmt/.venv/lib/python3.11/site-packages/sqlalchemy/orm/query.py", line 2826, in _iter
    result: Union[ScalarResult[_T], Result[_T]] = self.session.execute(
                                                  ^^^^^^^^^^^^^^^^^^^^^
  File "/Users/rtm/Documents/GitHub/work/utils/online-poc-mgmt/.venv/lib/python3.11/site-packages/sqlalchemy/orm/session.py", line 2306, in execute
    return self._execute_internal(
           ^^^^^^^^^^^^^^^^^^^^^^^
  File "/Users/rtm/Documents/GitHub/work/utils/online-poc-mgmt/.venv/lib/python3.11/site-packages/sqlalchemy/orm/session.py", line 2179, in _execute_internal
    bind = self.get_bind(**bind_arguments)
           ^^^^^^^^^^^^^^^^^^^^^^^^^^^^^^^
  File "/Users/rtm/Documents/GitHub/work/utils/online-poc-mgmt/.venv/lib/python3.11/site-packages/flask_sqlalchemy/session.py", line 53, in get_bind
    engines = self._db.engines
              ^^^^^^^^^^^^^^^^
  File "/Users/rtm/Documents/GitHub/work/utils/online-poc-mgmt/.venv/lib/python3.11/site-packages/flask_sqlalchemy/extension.py", line 690, in engines
    raise RuntimeError(
RuntimeError: The current Flask app is not registered with this 'SQLAlchemy' instance. Did you forget to call 'init_app', or did you create multiple 'SQLAlchemy' instances?
2025-03-19 19:40:25,618 INFO: POC Management startup [in /Users/rtm/Documents/GitHub/work/utils/online-poc-mgmt/app/__init__.py:40]
2025-03-19 19:41:55,922 INFO: POC Management startup [in /Users/rtm/Documents/GitHub/work/utils/online-poc-mgmt/app/__init__.py:40]
2025-03-19 19:42:44,774 INFO: POC Management startup [in /Users/rtm/Documents/GitHub/work/utils/online-poc-mgmt/app/__init__.py:40]
2025-03-19 19:45:38,645 INFO: POC Management startup [in /Users/rtm/Documents/GitHub/work/utils/online-poc-mgmt/app/__init__.py:40]
2025-03-19 19:48:00,509 INFO: POC Management startup [in /Users/rtm/Documents/GitHub/work/utils/online-poc-mgmt/app/__init__.py:40]
2025-03-19 19:49:59,444 INFO: POC Management startup [in /Users/rtm/Documents/GitHub/work/utils/online-poc-mgmt/app/__init__.py:40]
2025-03-19 19:51:09,800 INFO: POC Management startup [in /Users/rtm/Documents/GitHub/work/utils/online-poc-mgmt/app/__init__.py:40]
2025-03-19 19:52:17,648 INFO: POC Management startup [in /Users/rtm/Documents/GitHub/work/utils/online-poc-mgmt/app/__init__.py:40]
